<?xml version="1.0" encoding="utf-8"?>
<!-- This URDF was automatically created by SolidWorks to URDF Exporter! Originally created by Stephen Brawner (brawner@gmail.com) 
     Commit Version: 1.6.0-4-g7f85cfe  Build Version: 1.6.7995.38578
     For more information, please see http://wiki.ros.org/sw_urdf_exporter -->
<robot xmlns:xacro="http://ros.org/wiki/xacro" name="uavcar">
<xacro:include filename="$(find uavionics_workshop2)/urdf/gazebo_plugin.xacro" />

	<material name = "black">
		<color rgba="0 0 0 1"/>
	</material>
	<material name = "red">
		<color rgba="1 0 0 1"/>
	</material>
	<material name = "green">
		<color rgba="0 1 0 1"/>
	</material>
	<material name = "blue">
		<color rgba="0 0 1 1"/>
	</material>
	<material name = "yellow">
		<color rgba="1 1 0 1"/>
	</material>
	<material name = "white">
		<color rgba="1 1 1 1"/>
	</material>

  <link
    name="base_link">
    <inertial>
      <origin
        xyz="0.00147899999820755 0.0188763352547597 0.0134745939671567"
        rpy="0 0 0" />
      <mass
        value="0.177282637029181" />
      <inertia
        ixx="0.000202760531211198"
        ixy="5.60378040344759E-09"
        ixz="3.36864713263478E-08"
        iyy="0.000261966966777859"
        iyz="-2.91877091751572E-07"
        izz="9.32834509325526E-05" />
    </inertial>
    <visual>
      <origin
        xyz="0 0 0"
        rpy="0 0 0" />
      <geometry>
        <mesh
          filename="package://uavionics_workshop2/meshes/base_link.STL" />
      </geometry>
      <material
        name="">
        <color
          rgba="0.984313725490196 0.980392156862745 0.96078431372549 1" />
      </material>
    </visual>
    <collision>
      <origin
        xyz="0 0 0"
        rpy="0 0 0" />
      <geometry>
        <mesh
          filename="package://uavionics_workshop2/meshes/base_link.STL" />
      </geometry>
    </collision>
  </link>
<!-- Ball caster -->
  <link
    name="caster_link">
    <inertial>
      <origin
        xyz="4.33680868994202E-19 0 0"
        rpy="0 0 0" />
      <mass
        value="0.0114940403219339" />
      <inertia
        ixx="9.01132761239615E-07"
        ixy="-4.63221143029696E-23"
        ixz="9.26442286059391E-24"
        iyy="9.01132761239615E-07"
        iyz="1.96868985787621E-23"
        izz="9.01132761239615E-07" />
    </inertial>
    <visual>
      <origin
        xyz="0 0 0"
        rpy="0 0 0" />
      <geometry>
        <mesh
          filename="package://uavionics_workshop2/meshes/caster_link.STL" />
      </geometry>
      <material
        name="">
        <color
          rgba="0.792156862745098 0.819607843137255 0.933333333333333 1" />
      </material>
    </visual>
    <collision>
      <origin
        xyz="0 0 0"
        rpy="0 0 0" />
      <geometry>
        <mesh
          filename="package://uavionics_workshop2/meshes/caster_link.STL" />
      </geometry>
    </collision>
  </link>
  <joint
    name="caster_joint"
    type="continuous">
    <origin
      xyz="0.0028624 0.039118 -0.015737"
      rpy="1.5708 0 0" />
    <parent
      link="base_link" />
    <child
      link="caster_link" />
    <axis
      xyz="0 0 0" />
  </joint>

  <!-- Left wheel -->
  <link
    name="left_wheel_link">
    <inertial>
      <origin
        xyz="-0.00933674073330593 0.0137980057502908 -0.00927693681691629"
        rpy="0 0 0" />
      <mass
        value="0.026419137801914" />
      <inertia
        ixx="2.21976511661251E-05"
        ixy="2.16381805218921E-15"
        ixz="4.47703179372755E-16"
        iyy="1.18487420682976E-05"
        iyz="-1.92054842461658E-14"
        izz="1.18489017629898E-05" />
    </inertial>
    <visual>
      <origin
        xyz="0 0 0"
        rpy="0 0 0" />
      <geometry>
        <mesh
          filename="package://uavionics_workshop2/meshes/bl_wheel_link.STL" />
      </geometry>
      <material
        name="">
        <color
          rgba="0.792156862745098 0.819607843137255 0.933333333333333 1" />
      </material>
    </visual>
    <collision>
      <origin
        xyz="0 0 0"
        rpy="0 0 0" />
      <geometry>
        <mesh
          filename="package://uavionics_workshop2/meshes/bl_wheel_link.STL" />
      </geometry>
    </collision>
  </link>
  <joint
    name="left_wheel_joint"
    type="continuous">
    <origin
      xyz="-0.052447 -0.052231 -0.0091276"
      rpy="1.5708 0 0" />
    <parent
      link="base_link" />
    <child
      link="left_wheel_link" />
    <axis
      xyz="0 0 0" />
  </joint>
  <!-- Right wheel -->
  <link
    name="right_wheel_link">
    <inertial>
      <origin
        xyz="0.00933674073330604 0.0137980057502908 0.0092769368169147"
        rpy="0 0 0" />
      <mass
        value="0.026419137801914" />
      <inertia
        ixx="2.21976511661251E-05"
        ixy="-2.16381780280678E-15"
        ixz="4.475950864416E-16"
        iyy="1.18487420682976E-05"
        iyz="1.92054774246959E-14"
        izz="1.18489017629898E-05" />
    </inertial>
    <visual>
      <origin
        xyz="0 0 0"
        rpy="0 0 0" />
      <geometry>
        <mesh
          filename="package://uavionics_workshop2/meshes/br_wheel_link.STL" />
      </geometry>
      <material
        name="">
        <color
          rgba="0.792156862745098 0.819607843137255 0.933333333333333 1" />
      </material>
    </visual>
    <collision>
      <origin
        xyz="0 0 0"
        rpy="0 0 0" />
      <geometry>
        <mesh
          filename="package://uavionics_workshop2/meshes/br_wheel_link.STL" />
      </geometry>
    </collision>
  </link>
  <joint
    name="right_wheel_joint"
    type="continuous">
    <origin
      xyz="0.055629 -0.033677 -0.0091276"
      rpy="1.5708 0 0" />
    <parent
      link="base_link" />
    <child
      link="right_wheel_link" />
    <axis
      xyz="0 0 0" />
  </joint>
  <!-- Ultrasonic sensor -->
   <link
    name="ultrasonic_link">
    <inertial>
      <origin
        xyz="-0.00199122837107653 0.00279169071619218 -3.46944695195361E-18"
        rpy="0 0 0" />
      <mass
        value="0.00191039816339745" />
      <inertia
        ixx="3.47286799039144E-08"
        ixy="1.64823002157458E-21"
        ixz="6.46407968803954E-24"
        iyy="1.53770737048943E-07"
        iyz="5.68335243188381E-24"
        izz="1.36494439910389E-07" />
    </inertial>
    <visual>
      <origin
        xyz="0 0 0"
        rpy="0 0 0" />
      <geometry>
        <mesh
          filename="package://uavionics_workshop2/meshes/ultrasonic_link.STL" />
      </geometry>
      <material
        name="">
        <color
          rgba="0.792156862745098 0.819607843137255 0.933333333333333 1" />
      </material>
    </visual>
    <collision>
      <origin
        xyz="0 0 0"
        rpy="0 0 0" />
      <geometry>
        <mesh
          filename="package://uavionics_workshop2/meshes/ultrasonic_link.STL" />
      </geometry>
    </collision>
  </link>
  <joint
    name="ultrasonic_joint"
    type="fixed">
    <origin
      xyz="0 0.051648 0.01217"
      rpy="3.1416 0 1.57" />
    <parent
      link="base_link" />
    <child
      link="ultrasonic_link" />
    <axis
      xyz="0 0 0" />
    <limit
      lower="0"
      upper="0"
      effort="0"
      velocity="0" />
  </joint>
  <!-- Camera -->
  <link
    name="camera_link">
    <inertial>
      <origin
        xyz="1.47256989588285E-13 0.00113811950909846 7.30665528081431E-14"
        rpy="0 0 0" />
      <mass
        value="0.000291398223686155" />
      <inertia
        ixx="3.07398078263368E-09"
        ixy="1.88715983890242E-23"
        ixz="-3.27659631412719E-25"
        iyy="5.78718578948925E-09"
        iyz="-7.69801121642549E-26"
        izz="3.07398078263368E-09" />
    </inertial>
    <visual>
      <origin
        xyz="0 0 0"
        rpy="0 0 0" />
      <geometry>
        <mesh
          filename="package://uavionics_workshop2/meshes/camera_link.STL" />
      </geometry>
      <material
        name="">
        <color
          rgba="0.792156862745098 0.819607843137255 0.933333333333333 1" />
      </material>
    </visual>
    <collision>
      <origin
        xyz="0 0 0"
        rpy="0 0 0" />
      <geometry>
        <mesh
          filename="package://uavionics_workshop2/meshes/camera_link.STL" />
      </geometry>
    </collision>
  </link>
  <joint
    name="camera_joint"
    type="fixed">
    <origin
      xyz="0.0015589 0.045046 0.031152"
      rpy="0 0 1.57" />
    <parent
      link="base_link" />
    <child
      link="camera_link" />
    <axis
      xyz="0 0 0" />
  </joint>
  
  <transmission name="left_wheel_trans">
    <type>transmission_interface/SimpleTransmission</type>
    <joint name="left_wheel_joint">
      <hardwareInterface>hardware_interface/VelocityJointInterface</hardwareInterface>
    </joint>
    <actuator name="L_motor">
      <hardwareInterface>hardware_interface/VelocityJointInterface</hardwareInterface>
      <mechanicalReduction>1</mechanicalReduction>
    </actuator>
  </transmission>

  <transmission name="right_wheel_link">
    <type>transmission_interface/SimpleTransmission</type>
    <joint name="right_wheel_joint">
      <hardwareInterface>hardware_interface/VelocityJointInterface</hardwareInterface>
    </joint>
    <actuator name="R_motor">
      <hardwareInterface>hardware_interface/VelocityJointInterface</hardwareInterface>
      <mechanicalReduction>1</mechanicalReduction>
    </actuator>
  </transmission>

</robot>
