<?xml version="1.0" encoding="utf-8"?>
<!-- This URDF was automatically created by SolidWorks to URDF Exporter! Originally created by Stephen Brawner (brawner@gmail.com) 
     Commit Version: 1.6.0-4-g7f85cfe  Build Version: 1.6.7995.38578
     For more information, please see http://wiki.ros.org/sw_urdf_exporter -->
<robot xmlns:xacro="http://ros.org/wiki/xacro" name="uavcar">
<xacro:include filename="$(find uavionics_workshop2)/urdf/gazebo_plugin.xacro" />
	
  <material name = "black">
		<color rgba="0 0 0 1"/>
	</material>
	<material name = "red">
		<color rgba="1 0 0 1"/>
	</material>
	<material name = "green">
		<color rgba="0 1 0 1"/>
	</material>
	<material name = "blue">
		<color rgba="0 0 1 1"/>
	</material>
	<material name = "yellow">
		<color rgba="1 1 0 1"/>
	</material>
	<material name = "white">
		<color rgba="1 1 1 1"/>
	</material>

  <link
    name="base_link">
    <inertial>
      <origin
        xyz="-3.28475455401397E-06 -0.000998760054247713 0.00060735367389868"
        rpy="0 0 0" />
      <mass
        value="0.38105520656002" />
      <inertia
        ixx="0.000472947077248781"
        ixy="1.2692018595379E-09"
        ixz="7.75196238075727E-11"
        iyy="0.00034676867412049"
        iyz="-1.5941325677433E-05"
        izz="0.000750964235400176" />
    </inertial>
    <visual>
      <origin
        xyz="0 -0.013 -0.007"
        rpy="0 0 0" />
      <geometry>
        <mesh
          filename="package://uavionics_workshop2/meshes/base_link_visual.STL" />
      </geometry>
      <material
        name="">
        <color
          rgba="0.984313725490196 0.980392156862745 0.96078431372549 1" />
      </material>
    </visual>
    <collision>
      <origin
        xyz="0 0 0"
        rpy="0 0 0" />
      <geometry>
        <mesh
          filename="package://uavionics_workshop2/meshes/base_link_collision.STL" />
      </geometry>
    </collision>
  </link>
  <!-- Ball caster -->
  <link
    name="caster_link">
    <inertial>
      <origin
        xyz="-8.1315E-20 0 0"
        rpy="0 0 0" />
      <mass
        value="0.011494" />
      <inertia
        ixx="9.0113E-07"
        ixy="2.6915E-23"
        ixz="-7.1681E-23"
        iyy="9.0113E-07"
        iyz="-9.0241E-24"
        izz="9.0113E-07" />
    </inertial>
    <visual>
      <origin
        xyz="0 0 0"
        rpy="0 0 0" />
      <geometry>
        <mesh
          filename="package://uavionics_workshop2/meshes/caster_link.STL" />
      </geometry>
      <material
        name="">
        <color
          rgba="0.79216 0.81961 0.93333 1" />
      </material>
    </visual>
    <collision>
      <origin
        xyz="0 0 0"
        rpy="0 0 0" />
      <geometry>
        <mesh
          filename="package://uavionics_workshop2/meshes/caster_link.STL" />
      </geometry>
    </collision>
  </link>
  <joint
    name="caster_joint"
    type="continuous">
    <origin
      xyz="-0.00024045 -0.065116 -0.032659"
      rpy="1.5708 0 0" />
    <parent
      link="base_link" />
    <child
      link="caster_link" />
    <axis
      xyz="0 0 0" />
  </joint>

  <!-- Left wheel -->
    <link
    name="left_wheel_link">
    <inertial>
      <origin
        xyz="-7.3642E-14 1.2624E-12 0.030063"
        rpy="0 0 0" />
      <mass
        value="0.064596" />
      <inertia
        ixx="1.864E-05"
        ixy="-9.0163E-12"
        ixz="4.8348E-17"
        iyy="1.864E-05"
        iyz="-8.5442E-16"
        izz="3.2943E-05" />
    </inertial>
    <visual>
      <origin
        xyz="0 0 0"
        rpy="0 0 0" />
      <geometry>
        <mesh
          filename="package://uavionics_workshop2/meshes/left_wheel_link_collision.STL" />
      </geometry>
      <material
        name="">
        <color
          rgba="0.79216 0.81961 0.93333 1" />
      </material>
    </visual>
    <collision>
      <origin
        xyz="0 0 0"
        rpy="0 0 0" />
      <geometry>
        <mesh
          filename="package://uavionics_workshop2/meshes/left_wheel_link_collision.STL" />
      </geometry>
    </collision>
  </link>
  <joint
    name="left_wheel_joint"
    type="continuous">
    <origin
      xyz="0.03232 0.02433 -0.012594"
      rpy="-1.5708 0 -1.5708" />
    <parent
      link="base_link" />
    <child
      link="left_wheel_link" />
    <axis
      xyz="0 0 1" />
  </joint>
  <!-- Right wheel -->
  <link
    name="right_wheel_link">
    <inertial>
      <origin
        xyz="-7.2525E-14 -1.2626E-12 -0.030063"
        rpy="0 0 0" />
      <mass
        value="0.064596" />
      <inertia
        ixx="1.864E-05"
        ixy="9.0163E-12"
        ixz="-4.8448E-17"
        iyy="1.864E-05"
        iyz="-8.5442E-16"
        izz="3.2943E-05" />
    </inertial>
    <visual>
      <origin
        xyz="0 0 0"
        rpy="0 0 0" />
      <geometry>
        <mesh
          filename="package://uavionics_workshop2/meshes/right_wheel_link_collision.STL" />
      </geometry>
      <material
        name="">
        <color
          rgba="0.79216 0.81961 0.93333 1" />
      </material>
    </visual>
    <collision>
      <origin
        xyz="0 0 0"
        rpy="0 0 0" />
      <geometry>
        <mesh
          filename="package://uavionics_workshop2/meshes/right_wheel_link_collision.STL" />
      </geometry>
    </collision>
  </link>
  <joint
    name="right_wheel_joint"
    type="continuous">
    <origin
      xyz="-0.03232 0.02433 -0.012594"
      rpy="1.5708 0 1.5708" />
    <parent
      link="base_link" />
    <child
      link="right_wheel_link" />
    <axis
      xyz="0 0 1" />
  </joint>
<!-- Ultrasonic sensor -->
  <link
    name="ultrasonic_link">
    <inertial>
      <origin
        xyz="1.7697E-05 0.002797 3.8953E-06"
        rpy="0 0 0" />
      <mass
        value="0.0019064" />
      <inertia
        ixx="3.4686E-08"
        ixy="8.5467E-11"
        ixz="6.2881E-11"
        iyy="1.5347E-07"
        iyz="1.8914E-11"
        izz="1.3618E-07" />
    </inertial>
    <visual>
      <origin
        xyz="0 0 0"
        rpy="0 0 0" />
      <geometry>
        <mesh
          filename="package://uavionics_workshop2/meshes/ultrasonic_link.STL" />
      </geometry>
      <material
        name="">
        <color
          rgba="0.79216 0.81961 0.93333 1" />
      </material>
    </visual>
    <collision>
      <origin
        xyz="0 0 0"
        rpy="0 0 0" />
      <geometry>
        <mesh
          filename="package://uavionics_workshop2/meshes/ultrasonic_link.STL" />
      </geometry>
    </collision>
  </link>
  <joint
    name="ultrasonic_joint"
    type="fixed">
    <origin
      xyz="0 -0.05827 -0.0045938"
      rpy="0 0 -3.1416" />
    <parent
      link="base_link" />
    <child
      link="ultrasonic_link" />
    <axis
      xyz="0 0 0" />
  </joint>
  <!-- Camera -->
  <link
    name="camera_link">
    <inertial>
      <origin
        xyz="-1.7521E-16 0.0011504 -9.5353E-08"
        rpy="0 0 0" />
      <mass
        value="0.00028743" />
      <inertia
        ixx="3.0682E-09"
        ixy="-9.4191E-24"
        ixz="1.6544E-25"
        iyy="5.7822E-09"
        iyz="-1.0998E-25"
        izz="3.0682E-09" />
    </inertial>
    <visual>
      <origin
        xyz="0 0 0"
        rpy="0 0 0" />
      <geometry>
        <mesh
          filename="package://uavionics_workshop2/meshes/camera_link.STL" />
      </geometry>
      <material
        name="">
        <color
          rgba="0.79216 0.81961 0.93333 1" />
      </material>
    </visual>
    <collision>
      <origin
        xyz="0 0 0"
        rpy="0 0 0" />
      <geometry>
        <mesh
          filename="package://uavionics_workshop2/meshes/camera_link.STL" />
      </geometry>
    </collision>
  </link>
  <joint
    name="camera_joint"
    type="fixed">
    <origin
      xyz="0 -0.04927 0.011896"
      rpy="0 0 3.14" />
    <parent
      link="base_link" />
    <child
      link="camera_link" />
    <axis
      xyz="0 0 0" />
  </joint>

  <transmission name="left_wheel_trans">
    <type>transmission_interface/SimpleTransmission</type>
    <joint name="left_wheel_joint">
      <hardwareInterface>hardware_interface/VelocityJointInterface</hardwareInterface>
    </joint>
    <actuator name="L_motor">
      <hardwareInterface>hardware_interface/VelocityJointInterface</hardwareInterface>
      <mechanicalReduction>1</mechanicalReduction>
    </actuator>
  </transmission>

  <transmission name="right_wheel_trans">
    <type>transmission_interface/SimpleTransmission</type>
    <joint name="right_wheel_joint">
      <hardwareInterface>hardware_interface/VelocityJointInterface</hardwareInterface>
    </joint>
    <actuator name="R_motor">
      <hardwareInterface>hardware_interface/VelocityJointInterface</hardwareInterface>
      <mechanicalReduction>1</mechanicalReduction>
    </actuator>
  </transmission>
  
</robot>