<?xml version="1.0" encoding="utf-8"?>
<!-- This URDF was automatically created by SolidWorks to URDF Exporter! Originally created by Stephen Brawner (brawner@gmail.com) 
     Commit Version: 1.6.0-4-g7f85cfe  Build Version: 1.6.7995.38578
     For more information, please see http://wiki.ros.org/sw_urdf_exporter -->
<robot xmlns:xacro="http://ros.org/wiki/xacro" name="uavcar">
<xacro:include filename="$(find uavcar)/urdf/gazebo_plugin.xacro" />

	<material name = "black">
		<color rgba="0 0 0 1"/>
	</material>
	<material name = "red">
		<color rgba="1 0 0 1"/>
	</material>
	<material name = "green">
		<color rgba="0 1 0 1"/>
	</material>
	<material name = "blue">
		<color rgba="0 0 1 1"/>
	</material>
	<material name = "yellow">
		<color rgba="1 1 0 1"/>
	</material>
	<material name = "white">
		<color rgba="1 1 1 1"/>
	</material>

  <link
    name="base_link">
    <inertial>
      <origin
        xyz="0.00146931155818059 0.0202547315015083 0.00383279508656678"
        rpy="0 0 0" />
      <mass
        value="0.219401679394642" />
      <inertia
        ixx="0.000208124167049704"
        ixy="5.60378040345074E-09"
        ixz="3.36864713263349E-08"
        iyy="0.000263070736031005"
        iyz="-2.91877091751583E-07"
        izz="9.82049287222583E-05" />
    </inertial>
    <visual>
      <origin
        xyz="0 0 0"
        rpy="0 0 0" />
      <geometry>
        <mesh
          filename="package://uavcar/meshes/base_link.STL" />
      </geometry>
      <material
        name="black">
        <color
          rgba="0.984313725490196 0.980392156862745 0.96078431372549 1" />
      </material>
    </visual>
    <collision>
      <origin
        xyz="0 0 0"
        rpy="0 0 0" />
      <geometry>
        <mesh
          filename="package://uavcar/meshes/base_link.STL" />
      </geometry>
    </collision>
  </link>
  <link
    name="fl_wheel_link">
    <inertial>
      <origin
        xyz="0.00933674073330586 0.00927693681691626 -0.0137980057502913"
        rpy="0 0 0" />
      <mass
        value="0.026419137801914" />
      <inertia
        ixx="2.21976511661251E-05"
        ixy="4.47703357237612E-16"
        ixz="2.16374537517752E-15"
        iyy="1.18489017629898E-05"
        iyz="-1.92054790503463E-14"
        izz="1.18487420682976E-05" />
    </inertial>
    <visual>
      <origin
        xyz="0 0 0"
        rpy="0 0 0" />
      <geometry>
        <mesh
          filename="package://uavcar/meshes/fl_wheel_link.STL" />
      </geometry>
      <material
        name="red">
        <color
          rgba="0.792156862745098 0.819607843137255 0.933333333333333 1" />
      </material>
    </visual>
    <collision>
      <origin
        xyz="0 0 0"
        rpy="0 0 0" />
      <geometry>
        <mesh
          filename="package://uavcar/meshes/fl_wheel_link.STL" />
      </geometry>
    </collision>
  </link>
  <joint
    name="fl_wheel_joint"
    type="continuous">
    <origin
      xyz="-0.052447 0.050609 -0.0045225"
      rpy="1.5708 0 3.1416" />
    <parent
      link="base_link" />
    <child
      link="fl_wheel_link" />
    <axis
      xyz="0 0 0" />
  </joint>
  <link
    name="fr_wheel_link">
    <inertial>
      <origin
        xyz="0.00933674073330584 0.0092769368169169 -0.0137980057502909"
        rpy="0 0 0" />
      <mass
        value="0.026419137801914" />
      <inertia
        ixx="2.21976511661251E-05"
        ixy="4.47811464446858E-16"
        ixz="2.16381823941542E-15"
        iyy="1.18489017629898E-05"
        iyz="-1.92054815228219E-14"
        izz="1.18487420682976E-05" />
    </inertial>
    <visual>
      <origin
        xyz="0 0 0"
        rpy="0 0 0" />
      <geometry>
        <mesh
          filename="package://uavcar/meshes/fr_wheel_link.STL" />
      </geometry>
      <material
        name="red">
        <color
          rgba="0.792156862745098 0.819607843137255 0.933333333333333 1" />
      </material>
    </visual>
    <collision>
      <origin
        xyz="0 0 0"
        rpy="0 0 0" />
      <geometry>
        <mesh
          filename="package://uavcar/meshes/fr_wheel_link.STL" />
      </geometry>
    </collision>
  </link>
  <joint
    name="fr_wheel_joint"
    type="continuous">
    <origin
      xyz="0.055629 0.027769 0.018468"
      rpy="0 0 0" />
    <parent
      link="base_link" />
    <child
      link="fr_wheel_link" />
    <axis
      xyz="0 0 0" />
  </joint>
  <link
    name="bl_wheel_link">
    <inertial>
      <origin
        xyz="0.00933674073330595 0.00927693681691626 -0.0137980057502909"
        rpy="0 0 0" />
      <mass
        value="0.026419137801914" />
      <inertia
        ixx="2.21976511661251E-05"
        ixy="4.47703179377387E-16"
        ixz="2.16381625694231E-15"
        iyy="1.18489017629898E-05"
        iyz="-1.92054821918823E-14"
        izz="1.18487420682976E-05" />
    </inertial>
    <visual>
      <origin
        xyz="0 0 0"
        rpy="0 0 0" />
      <geometry>
        <mesh
          filename="package://uavcar/meshes/bl_wheel_link.STL" />
      </geometry>
      <material
        name="red">
        <color
          rgba="0.792156862745098 0.819607843137255 0.933333333333333 1" />
      </material>
    </visual>
    <collision>
      <origin
        xyz="0 0 0"
        rpy="0 0 0" />
      <geometry>
        <mesh
          filename="package://uavcar/meshes/bl_wheel_link.STL" />
      </geometry>
    </collision>
  </link>
  <joint
    name="bl_wheel_joint"
    type="continuous">
    <origin
      xyz="-0.052447 -0.052231 -0.0091276"
      rpy="-3.1416 0 -3.1416" />
    <parent
      link="base_link" />
    <child
      link="bl_wheel_link" />
    <axis
      xyz="0 0 0" />
  </joint>
  <link
    name="br_wheel_link">
    <inertial>
      <origin
        xyz="0.00933674073330602 0.00927693681691562 -0.0137980057502909"
        rpy="0 0 0" />
      <mass
        value="0.026419137801914" />
      <inertia
        ixx="2.21976511661251E-05"
        ixy="4.47596247242471E-16"
        ixz="2.16381736016141E-15"
        iyy="1.18489017629899E-05"
        iyz="-1.92054832982213E-14"
        izz="1.18487420682976E-05" />
    </inertial>
    <visual>
      <origin
        xyz="0 0 0"
        rpy="0 0 0" />
      <geometry>
        <mesh
          filename="package://uavcar/meshes/br_wheel_link.STL" />
      </geometry>
      <material
        name="red">
        <color
          rgba="0.792156862745098 0.819607843137255 0.933333333333333 1" />
      </material>
    </visual>
    <collision>
      <origin
        xyz="0 0 0"
        rpy="0 0 0" />
      <geometry>
        <mesh
          filename="package://uavcar/meshes/br_wheel_link.STL" />
      </geometry>
    </collision>
  </link>
  <joint
    name="br_wheel_joint"
    type="continuous">
    <origin
      xyz="0.055629 -0.033677 -0.0091276"
      rpy="-3.1416 0 0" />
    <parent
      link="base_link" />
    <child
      link="br_wheel_link" />
    <axis
      xyz="0 0 0" />
  </joint>
  <link
    name="ultrasonic_link">
    <inertial>
      <origin
        xyz="-0.00199122837139814 0.00279169071619218 -3.46944695195361E-18"
        rpy="0 0 0" />
      <mass
        value="0.00191039816339745" />
      <inertia
        ixx="3.47286799039144E-08"
        ixy="1.65247761678118E-21"
        ixz="7.08999414871017E-24"
        iyy="1.53770737048943E-07"
        iyz="5.93681768119573E-24"
        izz="1.36494439910389E-07" />
    </inertial>
    <visual>
      <origin
        xyz="0 0 0"
        rpy="0 0 0" />
      <geometry>
        <mesh
          filename="package://uavcar/meshes/ultrasonic_link.STL" />
      </geometry>
      <material
        name="yellow">
        <color
          rgba="0.792156862745098 0.819607843137255 0.933333333333333 1" />
      </material>
    </visual>
    <collision>
      <origin
        xyz="0 0 0"
        rpy="0 0 0" />
      <geometry>
        <mesh
          filename="package://uavcar/meshes/ultrasonic_link.STL" />
      </geometry>
    </collision>
  </link>
  <joint
    name="ultrasonic_joint"
    type="fixed">
    <origin
      xyz="0 0.051648 0.01217"
      rpy="3.1416 0 3.1416" />
    <parent
      link="base_link" />
    <child
      link="ultrasonic_link" />
    <axis
      xyz="1 0 0" />
    <limit
      lower="0"
      upper="0"
      effort="0"
      velocity="0" />
  </joint>
  <link
    name="camera_link">
    <inertial>
      <origin
        xyz="3.22441726097189E-16 0.00113811950909846 1.52655665885959E-16"
        rpy="0 0 0" />
      <mass
        value="0.000291398223686155" />
      <inertia
        ixx="3.07398078263368E-09"
        ixy="1.8881694501457E-23"
        ixz="-5.46121795190631E-25"
        iyy="5.78718578948925E-09"
        iyz="-3.56408474223639E-27"
        izz="3.07398078263368E-09" />
    </inertial>
    <visual>
      <origin
        xyz="0 0 0"
        rpy="0 0 0" />
      <geometry>
        <mesh
          filename="package://uavcar/meshes/camera_link.STL" />
      </geometry>
      <material
        name="green">
        <color
          rgba="0.792156862745098 0.819607843137255 0.933333333333333 1" />
      </material>
    </visual>
    <collision>
      <origin
        xyz="0 0 0"
        rpy="0 0 0" />
      <geometry>
        <mesh
          filename="package://uavcar/meshes/camera_link.STL" />
      </geometry>
    </collision>
  </link>
  <joint
    name="camera_joint"
    type="fixed">
    <origin
      xyz="0.00155886395139227 0.0450456398524161 0.031152378379546"
      rpy="-3.14159265358979 0 3.14159265358979" />
    <parent
      link="base_link" />
    <child
      link="camera_link" />
    <axis
      xyz="1 0 0" />
  </joint>
</robot>