<?xml version="1.0" encoding="utf-8"?>
<!-- This URDF was automatically created by SolidWorks to URDF Exporter! Originally created by Stephen Brawner (brawner@gmail.com) 
     Commit Version: 1.6.0-4-g7f85cfe  Build Version: 1.6.7995.38578
     For more information, please see http://wiki.ros.org/sw_urdf_exporter -->
<robot xmlns:xacro="http://ros.org/wiki/xacro" name="uavcar">
<xacro:include filename="$(find uavionics_workshop2)/urdf/gazebo_plugin.xacro" />

	<material name = "black">
		<color rgba="0 0 0 1"/>
	</material>
	<material name = "red">
		<color rgba="1 0 0 1"/>
	</material>
	<material name = "green">
		<color rgba="0 1 0 1"/>
	</material>
	<material name = "blue">
		<color rgba="0 0 1 1"/>
	</material>
	<material name = "yellow">
		<color rgba="1 1 0 1"/>
	</material>
	<material name = "white">
		<color rgba="1 1 1 1"/>
	</material>

  <link
    name="base_link">
    <inertial>
      <origin
        xyz="0.00147824407270064 0.0189723086974158 0.0132754326650664"
        rpy="0 0 0" />
      <mass
        value="0.176092976683929" />
      <inertia
        ixx="0.000202756098868745"
        ixy="5.60378040345227E-09"
        ixz="3.3686471326345E-08"
        iyy="0.000261893787679529"
        iyz="-2.91877091751573E-07"
        izz="9.32105895772371E-05" />
    </inertial>
    <visual>
      <origin
        xyz="0 0 0"
        rpy="0 0 0" />
      <geometry>
        <mesh
          filename="package://uavionics_workshop2/meshes/base_link.STL" />
      </geometry>
      <material
        name="">
        <color
          rgba="0.984313725490196 0.980392156862745 0.96078431372549 1" />
      </material>
    </visual>
    <collision>
      <origin
        xyz="0 0 0"
        rpy="0 0 0" />
      <geometry>
        <mesh
          filename="package://uavionics_workshop2/meshes/base_link.STL" />
      </geometry>
    </collision>
  </link>
<!-- Ball caster -->
  <link
    name="caster_link">
    <inertial>
      <origin
        xyz="0 -4.33680868994202E-19 0"
        rpy="0 0 0" />
      <mass
        value="0.0114940403219339" />
      <inertia
        ixx="9.01132761239615E-07"
        ixy="9.26442286059391E-24"
        ixz="-1.96868985787621E-23"
        iyy="9.01132761239615E-07"
        iyz="4.63221143029696E-23"
        izz="9.01132761239615E-07" />
    </inertial>
    <visual>
      <origin
        xyz="0 0 0"
        rpy="0 0 0" />
      <geometry>
        <mesh
          filename="package://uavionics_workshop2/meshes/caster_link.STL" />
      </geometry>
      <material
        name="">
        <color
          rgba="0.792156862745098 0.819607843137255 0.933333333333333 1" />
      </material>
    </visual>
    <collision>
      <origin
        xyz="0 0 0"
        rpy="0 0 0" />
      <geometry>
        <mesh
          filename="package://uavionics_workshop2/meshes/caster_link.STL" />
      </geometry>
    </collision>
  </link>
  <joint
    name="caster_joint"
    type="continuous">
    <origin
      xyz="0.0028624 0.039118 -0.015737"
      rpy="0 0 1.5708" />
    <parent
      link="base_link" />
    <child
      link="caster_link" />
    <axis
      xyz="0 0 0" />
  </joint>

  <!-- Left wheel -->
  <link
    name="left_wheel_link">
    <inertial>
      <origin
        xyz="0.0136547670195108 -3.51930082298502E-11 -6.44661476978392E-11"
        rpy="0 0 0" />
      <mass
        value="0.026419137801914" />
      <inertia
        ixx="2.21976511661251E-05"
        ixy="4.47612824651767E-16"
        ixz="2.16382404897084E-15"
        iyy="1.18489017629898E-05"
        iyz="-1.92054732153882E-14"
        izz="1.18487420682976E-05" />
    </inertial>
    <visual>
      <origin
        xyz="0 0 0"
        rpy="0 0 0" />
      <geometry>
        <mesh
          filename="package://uavionics_workshop2/meshes/left_wheel_link.STL" />
      </geometry>
      <material
        name="">
        <color
          rgba="0.792156862745098 0.819607843137255 0.933333333333333 1" />
      </material>
    </visual>
    <collision>
      <origin
        xyz="0 0 0"
        rpy="0 0 0" />
      <geometry>
        <mesh
          filename="package://uavionics_workshop2/meshes/left_wheel_link.STL" />
      </geometry>
    </collision>
  </link>
  <joint
    name="left_wheel_joint"
    type="continuous">
    <origin
      xyz="-0.048089 -0.042954 0.0046704"
      rpy="0 0 3.1416" />
    <parent
      link="base_link" />
    <child
      link="left_wheel_link" />
    <axis
      xyz="1 0 0" />
  </joint>
  <!-- Right wheel -->
  <link
    name="right_wheel_link">
    <inertial>
      <origin
        xyz="0.0136547670195105 -3.51918702512499E-11 -6.44666060985177E-11"
        rpy="0 0 0" />
      <mass
        value="0.0264191378019141" />
      <inertia
        ixx="2.21976511661251E-05"
        ixy="4.47737318036792E-16"
        ixz="2.16381665820078E-15"
        iyy="1.18489017629898E-05"
        iyz="-1.92054800445913E-14"
        izz="1.18487420682976E-05" />
    </inertial>
    <visual>
      <origin
        xyz="0 0 0"
        rpy="0 0 0" />
      <geometry>
        <mesh
          filename="package://uavionics_workshop2/meshes/right_wheel_link.STL" />
      </geometry>
      <material
        name="">
        <color
          rgba="0.792156862745098 0.819607843137255 0.933333333333333 1" />
      </material>
    </visual>
    <collision>
      <origin
        xyz="0 0 0"
        rpy="0 0 0" />
      <geometry>
        <mesh
          filename="package://uavionics_workshop2/meshes/right_wheel_link.STL" />
      </geometry>
    </collision>
  </link>
  <joint
    name="right_wheel_joint"
    type="continuous">
    <origin
      xyz="0.051271 -0.042954 0.0046704"
      rpy="0 0 0" />
    <parent
      link="base_link" />
    <child
      link="right_wheel_link" />
    <axis
      xyz="1 0 0" />
  </joint>
  <!-- Ultrasonic sensor -->
  <link
    name="ultrasonic_link">
    <inertial>
      <origin
        xyz="0.00846760153918975 0.00279698511486075 0.00187389525186803"
        rpy="0 0 0" />
      <mass
        value="0.00190642703320368" />
      <inertia
        ixx="3.46864640463999E-08"
        ixy="8.54667602133522E-11"
        ixz="6.28805230238285E-11"
        iyy="1.53467662508661E-07"
        iyz="1.89139457513764E-11"
        izz="1.3618200036245E-07" />
    </inertial>
    <visual>
      <origin
        xyz="0 0 0"
        rpy="0 0 0" />
      <geometry>
        <mesh
          filename="package://uavionics_workshop2/meshes/ultrasonic_link.STL" />
      </geometry>
      <material
        name="">
        <color
          rgba="0.792156862745098 0.819607843137255 0.933333333333333 1" />
      </material>
    </visual>
    <collision>
      <origin
        xyz="0 0 0"
        rpy="0 0 0" />
      <geometry>
        <mesh
          filename="package://uavionics_workshop2/meshes/ultrasonic_link.STL" />
      </geometry>
    </collision>
  </link>
  <joint
    name="ultrasonic_joint"
    type="fixed">
    <origin
      xyz="-0.0072137 0.051648 0.010322"
      rpy="0 0.00074274 0" />
    <parent
      link="base_link" />
    <child
      link="ultrasonic_link" />
    <axis
      xyz="0 0 0" />
    <limit
      lower="0"
      upper="0"
      effort="0"
      velocity="0" />
  </joint>
  <!-- Camera -->
   <link
    name="camera_link">
    <inertial>
      <origin
        xyz="1.60968287310492E-12 0.00113811950909846 7.98732607831809E-13"
        rpy="0 0 0" />
      <mass
        value="0.000291398223686155" />
      <inertia
        ixx="3.07398078263368E-09"
        ixy="1.88790158542446E-23"
        ixz="-3.27659631412719E-25"
        iyy="5.78718578948925E-09"
        iyz="-7.6064383812265E-26"
        izz="3.07398078263368E-09" />
    </inertial>
    <visual>
      <origin
        xyz="0 0 0"
        rpy="0 0 0" />
      <geometry>
        <mesh
          filename="package://uavionics_workshop2/meshes/camera_link.STL" />
      </geometry>
      <material
        name="">
        <color
          rgba="0.792156862745098 0.819607843137255 0.933333333333333 1" />
      </material>
    </visual>
    <collision>
      <origin
        xyz="0 0 0"
        rpy="0 0 0" />
      <geometry>
        <mesh
          filename="package://uavionics_workshop2/meshes/camera_link.STL" />
      </geometry>
    </collision>
  </link>
  <joint
    name="camera_joint"
    type="fixed">
    <origin
      xyz="0.0015589 0.045046 0.031152"
      rpy="-3.1416 0 3.1416" />
    <parent
      link="base_link" />
    <child
      link="camera_link" />
    <axis
      xyz="0 0 0" />
  </joint>

</robot>